Traceback (most recent call last):
  File "C:\Users\Sotiris\anaconda3\lib\site-packages\jupyter_cache\executors\utils.py", line 58, in single_nb_execution
    executenb(
  File "C:\Users\Sotiris\anaconda3\lib\site-packages\nbclient\client.py", line 1204, in execute
    return NotebookClient(nb=nb, resources=resources, km=km, **kwargs).execute()
  File "C:\Users\Sotiris\anaconda3\lib\site-packages\nbclient\util.py", line 84, in wrapped
    return just_run(coro(*args, **kwargs))
  File "C:\Users\Sotiris\anaconda3\lib\site-packages\nbclient\util.py", line 62, in just_run
    return loop.run_until_complete(coro)
  File "C:\Users\Sotiris\anaconda3\lib\asyncio\base_events.py", line 647, in run_until_complete
    return future.result()
  File "C:\Users\Sotiris\anaconda3\lib\site-packages\nbclient\client.py", line 663, in async_execute
    await self.async_execute_cell(
  File "C:\Users\Sotiris\anaconda3\lib\site-packages\nbclient\client.py", line 965, in async_execute_cell
    await self._check_raise_for_error(cell, cell_index, exec_reply)
  File "C:\Users\Sotiris\anaconda3\lib\site-packages\nbclient\client.py", line 862, in _check_raise_for_error
    raise CellExecutionError.from_cell_and_msg(cell, exec_reply_content)
nbclient.exceptions.CellExecutionError: An error occurred while executing the following cell:
------------------
xml_data = objectify.parse('generation_fuel_type_multiday.xml')  # Parse XML data
root = xml_data.getroot()
lst = []
data = []
cols = []

for i in root.getchildren():
  if str(type(i)) == "<class 'lxml.objectify.ObjectifiedElement'>":
    lst.append(i)
    cols.append(i.attrib['Series'])

for child in lst:
  tmp = child.getchildren()
  arr = []
  for subchild in tmp:
    val = subchild.getchildren()
    arr.append(val[0])
  data.append(arr)

print([len(data[0]), len(data[1]), len(data[2])])

for i in range(len(data)):
  data[i] = data[i][:-5]
  data[i] = list(map(float, data[i]))


df = pd.DataFrame(data).T
cols = ["Supply_" + name for name in cols]
df.columns = cols
df
------------------

[1;31m---------------------------------------------------------------------------[0m
[1;31mOSError[0m                                   Traceback (most recent call last)
Input [1;32mIn [2][0m, in [0;36m<cell line: 1>[1;34m()[0m
[1;32m----> 1[0m xml_data [38;5;241m=[39m [43mobjectify[49m[38;5;241;43m.[39;49m[43mparse[49m[43m([49m[38;5;124;43m'[39;49m[38;5;124;43mgeneration_fuel_type_multiday.xml[39;49m[38;5;124;43m'[39;49m[43m)[49m  [38;5;66;03m# Parse XML data[39;00m
[0;32m      2[0m root [38;5;241m=[39m xml_data[38;5;241m.[39mgetroot()
[0;32m      3[0m lst [38;5;241m=[39m []

File [1;32msrc/lxml/objectify.pyx:2044[0m, in [0;36mlxml.objectify.parse[1;34m()[0m

File [1;32msrc/lxml/etree.pyx:3536[0m, in [0;36mlxml.etree.parse[1;34m()[0m

File [1;32msrc/lxml/parser.pxi:1876[0m, in [0;36mlxml.etree._parseDocument[1;34m()[0m

File [1;32msrc/lxml/parser.pxi:1902[0m, in [0;36mlxml.etree._parseDocumentFromURL[1;34m()[0m

File [1;32msrc/lxml/parser.pxi:1805[0m, in [0;36mlxml.etree._parseDocFromFile[1;34m()[0m

File [1;32msrc/lxml/parser.pxi:1177[0m, in [0;36mlxml.etree._BaseParser._parseDocFromFile[1;34m()[0m

File [1;32msrc/lxml/parser.pxi:615[0m, in [0;36mlxml.etree._ParserContext._handleParseResultDoc[1;34m()[0m

File [1;32msrc/lxml/parser.pxi:725[0m, in [0;36mlxml.etree._handleParseResult[1;34m()[0m

File [1;32msrc/lxml/parser.pxi:652[0m, in [0;36mlxml.etree._raiseParseError[1;34m()[0m

[1;31mOSError[0m: Error reading file 'generation_fuel_type_multiday.xml': failed to load external entity "generation_fuel_type_multiday.xml"
OSError: Error reading file 'generation_fuel_type_multiday.xml': failed to load external entity "generation_fuel_type_multiday.xml"

